Workbook

Sheet Ringkasan & Insight
B2: ANALISIS ONLINE RETAIL DATASET (Des 2010 - Des 2011)
B3: UK-based online retailer - giftware & household items
B5: KPI UTAMA (Data Bersih, setelah exclude cancelled/adjustment)
B7: Total Revenue (GBP) | D7: 10259030
B8: Jumlah Order (distinct invoice) | D8: 19776
B9: Rata-rata Order Value / AOV (GBP) | D9: =D7/D8 -> 518.76164
B10: Jumlah Customer Unik | D10: 4334 | E10: exclude baris CustomerID kosong
B11: Jumlah Produk Unik (StockCode) | D11: 3914
B12: Jumlah Negara | D12: 38
B13: Periode Data | D13: 1 Des 2010 - 9 Des 2011 (Des 2011 TIDAK penuh sebulan)
B14: Revenue Hilang akibat Cancelled Order (GBP) | D14: 893979.73
B15: % Order yang Dibatalkan | D15: 0.017394918
B17: INSIGHT UTAMA
B18: 1. Konsentrasi pasar sangat tinggi di United Kingdom (sekitar 85% dari total revenue). Ekspansi/marketing di negara Eropa lain (Belanda, Irlandia, Jerman, Prancis) berpotensi jadi peluang pertumbuhan karena kontribusinya masih kecil relatif ke ukuran pasarnya.
B20: 2. Revenue naik tajam di Sep-Nov 2011 (puncak November, sekitar GBP 1,45 juta) - pola musiman jelang Natal. Desember 2011 di data ini hanya sampai tanggal 9, jadi angkanya TIDAK mencerminkan bulan penuh - jangan dibaca sebagai penurunan performa.
B22: 3. Toko TIDAK memiliki transaksi sama sekali di hari Sabtu (kemungkinan toko/gudang tutup weekend hari itu). Jam paling ramai adalah 10:00-15:00 - waktu ini ideal untuk promosi/live campaign.
B24: 4. Distribusi revenue customer sangat timpang (prinsip Pareto): top 20% customer (866 orang) menyumbang 74.6% revenue, dan hanya 1133 customer (26.1% dari total) sudah menyumbang 80% revenue. Retensi/loyalty program ke segmen kecil ini berdampak besar.
B26: 5. Produk 'PAPER CRAFT, LITTLE BIRDIE' (StockCode 23843) masuk 15 besar revenue karena SATU transaksi outlier: Invoice 581483, qty 80,995 unit @GBP2.08 oleh customer 16446. Angka ini kemungkinan pembelian grosir/wholesale, bukan pola beli ritel biasa - sebaiknya di-exclude dari analisis 'produk terlaris ritel' agar tidak menyesatkan.
B28: 6. 25% baris transaksi bersih tidak punya CustomerID (kemungkinan transaksi guest/tanpa akun). Ini valid untuk analisis revenue & produk, tapi HARUS dikeluarkan dari analisis customer/RFM (sudah dilakukan di sheet Pivot_Customer).
B30: 7. Cancelled order membuat kehilangan potensi revenue sekitar GBP 893,980 (1.7% dari order). Perlu digali lebih lanjut alasan pembatalan (stok habis? kualitas? kesalahan input?) - data ini tidak punya kolom alasan cancel, jadi butuh data tambahan dari tim CS/ops.
B33: REKOMENDASI BISNIS
B34: - Fokuskan budget marketing/ads untuk retensi ke top ~20% customer (lihat sheet Pivot_Customer) lewat program loyalty/exclusive discount - dampak revenue-nya jauh lebih besar dibanding akuisisi customer baru secara acak.
B35: - Siapkan stok & tenaga tambahan untuk periode Sep-Nov menjelang Natal; pertimbangkan pre-order/early bird campaign di Agustus untuk smoothing lonjakan permintaan.
B36: - Investigasi akar penyebab cancelled order (sekitar 1.7% dari order, senilai sekitar GBP 894rb) - kalau bisa diturunkan setengahnya saja, itu revenue tambahan signifikan tanpa perlu akuisisi customer baru.
... B38: - Dorong customer guest (tanpa CustomerID, 25% transaksi) untuk membuat akun - supaya bisa masuk program loyalty & data historinya bisa dianalisis untuk personalisasi.

Sheet Dashboard
B2: DASHBOARD - ONLINE RETAIL ANALYSIS
B4: UK-based online retailer (giftware & household items) · Periode: Des 2010 – Des 2011 (Des 2011 tidak penuh sebulan)
B6: TOTAL REVENUE (GBP) | D6: JUMLAH ORDER | F6: AOV (GBP) | H6: CUSTOMER UNIK | J6: PRODUK UNIK | L6: NEGARA | N6: % ORDER DIBATALKAN
B7: ='Ringkasan & Insight'!D7 -> 10259030 | D7: ='Ringkasan & Insight'!D8 -> 19776 | F7: ='Ringkasan & Insight'!D9 -> 518.76164 | H7: ='Ringkasan & Insight'!D10 -> 4334 | J7: ='Ringkasan & Insight'!D11 -> 3914 | L7: ='Ringkasan & Insight'!D12 -> 38 | N7: ='Ringkasan & Insight'!D15 -> 0.017394918
Y12: Row Labels | Z12: Revenue
Y13: 2010-12 | Z13: 775714.95
Y14: 2011-01 | Z14: 670439.46
Y15: 2011-02 | Z15: 507866.54
Y16: 2011-03 | Z16: 689841.84
Y17: 2011-04 | Z17: 515499.66
Y18: 2011-05 | Z18: 740036.33
Y19: 2011-06 | Z19: 737683.99
Y20: 2011-07 | Z20: 688252.67
Y21: 2011-08 | Z21: 735370.22
Y22: 2011-09 | Z22: 1028345.4
Y23: 2011-10 | Z23: 1103364
Y24: 2011-11 | Z24: 1452116
... Y26: Grand Total | Z26: 10259030
Y28: Row Labels | Z28: Sum of Revenue (GBP)
Y29: CHILLI LIGHTS | Z29: 54096.36
Y30: ASSORTED COLOUR BIRD ORNAMENT | Z30: 58927.62
Y31: PAPER CHAIN KIT 50'S CHRISTMAS | Z31: 64875.59
Y32: RABBIT NIGHT LIGHT | Z32: 66870.03
Y33: MEDIUM CERAMIC TOP STORAGE JAR | Z33: 81700.92
Y34: JUMBO BAG RED RETROSPOT | Z34: 94159.81
Y35: PARTY BUNTING | Z35: 99445.23
Y36: WHITE HANGING HEART T-LIGHT HOLDER | Z36: 104284.24
Y37: PAPER CRAFT , LITTLE BIRDIE | Z37: 168469.6
Y38: REGENCY CAKESTAND 3 TIER | Z38: 174156.54
Y39: Grand Total | Z39: 966985.94
Y42: Row Labels | Z42: Revenue
Y43: 16029 | Z43: 72708.09
Y44: 12346 | Z44: 77183.6
Y45: 17511 | Z45: 91062.38
Y46: 14156 | Z46: 116560.08
Y47: 12415 | Z47: 124564.53
Y48: 14911 | Z48: 136161.83
Y49: 16446 | Z49: 168472.5
Y50: 17450 | Z50: 194390.79
Y51: 18102 | Z51: 259657.3
...

Sheet Log_Pembersihan_Data
B2: LOG PEMBERSIHAN DATA (Data Cleaning Log)
B4: # | C4: Langkah Cleaning | D4: Alasan | E4: Baris Terdampak | F4: Baris Tersisa
B5: 1 | C5: Hapus baris duplikat exact | D5: Mencegah pencatatan ganda (double-entry) pada transaksi yang identik | E5: 5268 | F5: 536641
B6: 2 | C6: Pemisahan transaksi batal (Invoice prefix "C") | D6: Bukan penjualan riil; dianalisis terpisah di sheet Data_Cancelled utk cancellation rate | E6: 9251 | F6: 527390
B7: 3 | C7: Filter UnitPrice <= 0 | D7: Mengeliminasi data stock adjustment & write-off internal | E7: 2512 | F7: 524878
B8: 4 | C8: Filter Quantity <= 0 | D8: Mengeliminasi transaksi anomali dengan jumlah nol atau negatif | E8: 0 | F8: 524878
B9: 5 | C9: Filter kode administratif / non-produk | D9: Mengeluarkan kode biaya operasional (POST, DOT, BANK CHARGES, AMAZONFEE, dll.) | E9: 2307 | F9: 522571
B11: HASIL AKHIR: 522.571 baris siap dipakai untuk analisis penjualan (basis perhitungan seluruh pivot di workbook ini)
B12: + 9.251 baris cancelled disimpan terpisah (sheet Data_Cancelled) untuk analisis pembatalan

Sheet Data_Cleaned
A1: InvoiceNo | B1: StockCode | C1: Description | D1: Quantity | E1: InvoiceDate | F1: UnitPrice | G1: CustomerID | H1: Country | I1: TotalPrice | J1: YearMonth
A2: 536365 | B2: 21730 | C2: GLASS STAR FROSTED T-LIGHT HOLDER | D2: 6 | E2: 40513.351 | F2: 4.25 | G2: 17850 | H2: United Kingdom | I2: 25.5 | J2: 2010-12
A3: 536370 | B3: 10002 | C3: INFLATABLE POLITICAL GLOBE | D3: 48 | E3: 40513.365 | F3: 0.85 | G3: 12583 | H3: France | I3: 40.8 | J3: 2010-12
A4: 536373 | B4: 21871 | C4: SAVE THE PLANET MUG | D4: 6 | E4: 40513.376 | F4: 1.06 | G4: 17850 | H4: United Kingdom | I4: 6.36 | J4: 2010-12
A5: 536376 | B5: 22114 | C5: HOT WATER BOTTLE TEA AND SYMPATHY | D5: 48 | E5: 40513.397 | F5: 3.45 | G5: 15291 | H5: United Kingdom | I5: 165.6 | J5: 2010-12
A6: 536378 | B6: 21931 | C6: JUMBO STORAGE BAG SUKI | D6: 10 | E6: 40513.401 | F6: 1.95 | G6: 14688 | H6: United Kingdom | I6: 19.5 | J6: 2010-12
A7: 536378 | B7: 20723 | C7: STRAWBERRY CHARLOTTE BAG | D7: 10 | E7: 40513.401 | F7: 0.85 | G7: 14688 | H7: United Kingdom | I7: 8.5 | J7: 2010-12
A8: 536378 | B8: 85183B | C8: CHARLIE & LOLA WASTEPAPER BIN FLORA | D8: 48 | E8: 40513.401 | F8: 1.25 | G8: 14688 | H8: United Kingdom | I8: 60 | J8: 2010-12
A9: 536381 | B9: 21166 | C9: COOK WITH WINE METAL SIGN | D9: 1 | E9: 40513.403 | F9: 1.95 | G9: 15311 | H9: United Kingdom | I9: 1.95 | J9: 2010-12
A10: 536381 | B10: 84971S | C10: SMALL HEART FLOWERS HOOK | D10: 6 | E10: 40513.403 | F10: 0.85 | G10: 15311 | H10: United Kingdom | I10: 5.1 | J10: 2010-12
A11: 536381 | B11: 21557 | C11: SET OF 6 FUNKY BEAKERS | D11: 2 | E11: 40513.403 | F11: 2.95 | G11: 15311 | H11: United Kingdom | I11: 5.9 | J11: 2010-12
A12: 536384 | B12: 22470 | C12: HEART OF WICKER LARGE | D12: 40 | E12: 40513.412 | F12: 2.55 | G12: 18074 | H12: United Kingdom | I12: 102 | J12: 2010-12
A13: 536388 | B13: 21363 | C13: HOME SMALL WOOD LETTERS | D13: 3 | E13: 40513.416 | F13: 4.95 | G13: 16250 | H13: United Kingdom | I13: 14.85 | J13: 2010-12
... A80: 536542 | B80: 85099C | C80: JUMBO BAG BAROQUE BLACK WHITE | D80: 20 | E80: 40513.591 | F80: 1.95 | G80: 16456 | H80: United Kingdom | I80: 39 | J80: 2010-12
A81: 536544 | B81: 21165 | C81: BEWARE OF THE CAT METAL SIGN | D81: 1 | E81: 40513.606 | F81: 4.21 | H81: United Kingdom | I81: 4.21 | J81: 2010-12
A82: 536544 | B82: 90071 | C82: RUBY GLASS CLUSTER EARRINGS | D82: 1 | E82: 40513.606 | F82: 1.26 | H82: United Kingdom | I82: 1.26 | J82: 2010-12
A83: 536544 | B83: 85135C | C83: RED DRAGONFLY HELICOPTER | D83: 1 | E83: 40513.606 | F83: 8.47 | H83: United Kingdom | I83: 8.47 | J83: 2010-12
A84: 536544 | B84: 22962 | C84: JAM JAR WITH PINK LID | D84: 4 | E84: 40513.606 | F84: 1.66 | H84: United Kingdom | I84: 6.64 | J84: 2010-12
A85: 536544 | B85: 85135B | C85: BLUE DRAGONFLY HELICOPTER | D85: 1 | E85: 40513.606 | F85: 8.47 | H85: United Kingdom | I85: 8.47 | J85: 2010-12
A86: 536544 | B86: 22945 | C86: CHRISTMAS METAL TAGS ASSORTED | D86: 1 | E86: 40513.606 | F86: 11.02 | H86: United Kingdom | I86: 11.02 | J86: 2010-12
A87: 536544 | B87: 22515 | C87: CHILDS GARDEN SPADE PINK | D87: 1 | E87: 40513.606 | F87: 4.21 | H87: United Kingdom | I87: 4.21 | J87: 2010-12
A88: 536544 | B88: 84580 | C88: MOUSE TOY WITH PINK T-SHIRT | D88: 1 | E88: 40513.606 | F88: 4.21 | H88: United Kingdom | I88: 4.21 | J88: 2010-12
A89: 536544 | B89: 22224 | C89: WHITE LOVEBIRD LANTERN | D89: 1 | E89: 40513.606 | F89: 5.91 | H89: United Kingdom | I89: 5.91 | J89: 2010-12
A90: 536544 | B90: 20685 | C90: DOORMAT RED RETROSPOT | D90: 1 | E90: 40513.606 | F90: 14.43 | H90: United Kingdom | I90: 14.43 | J90: 2010-12
A91: 536544 | B91: 72586 | C91: SET OF 6 HALLOWEEN GHOST T-LIGHTS | D91: 1 | E91: 40513.606 | F91: 0.85 | H91: United Kingdom | I91: 0.85 | J91: 2010-12
A92: 536544 | B92: 22130 | C92: PARTY CONE CHRISTMAS DECORATION | D92: 2 | E92: 40513.606 | F92: 8.47 | H92: United Kingdom | I92: 16.94 | J92: 2010-12
... A110: 536544 | B110: 20971 | C110: PINK BLUE FELT CRAFT TRINKET BOX | D110: 1 | E110: 40513.606 | F110: 2.51 | H110: United Kingdom | I110: 2.51 | J110: 2010-12
A111: 536557 | B111: 22730 | C111: ALARM CLOCK BAKELIKE IVORY | D111: 1 | E111: 40513.612 | F111: 3.75 | G111: 17841 | H111: United Kingdom | I111: 3.75 | J111: 2010-12
A112: 536557 | B112: 22794 | C112: SWEETHEART WIRE MAGAZINE RACK | D112: 1 | E112: 40513.612 | F112: 7.95 | G112: 17841 | H112: United Kingdom | I112: 7.95 | J112: 2010-12
A113: 536559 | B113: 51014A | C113: FEATHER PEN,HOT PINK | D113: 12 | E113: 40513.621 | F113: 0.85 | G113: 17873 | H113: United Kingdom | I113: 10.2 | J113: 2010-12
A114: 536561 | B114: 22750 | C114: FELTCRAFT PRINCESS LOLA DOLL | D114: 4 | E114: 40513.629 | F114: 3.75 | G114: 12921 | H114: United Kingdom | I114: 15 | J114: 2010-12
A115: 536569 | B115: 22496 | C115: SET OF 2 ROUND TINS DUTCH CHEESE | D115: 1 | E115: 40513.649 | F115: 2.95 | G115: 16274 | H115: United Kingdom | I115: 2.95 | J115: 2010-12
A116: 536569 | B116: 22659 | C116: LUNCH BOX I LOVE LONDON | D116: 1 | E116: 40513.649 | F116: 1.95 | G116: 16274 | H116: United Kingdom | I116: 1.95 | J116: 2010-12
A117: 536569 | B117: 21147 | C117: JINGLE BELLS TREE DECORATION | D117: 2 | E117: 40513.649 | F117: 2.1 | G117: 16274 | H117: United Kingdom | I117: 4.2 | J117: 2010-12
A118: 536570 | B118: 84836 | C118: ZINC METAL HEART DECORATION | D118: 12 | E118: 40513.649 | F118: 1.25 | G118: 14496 | H118: United Kingdom | I118: 15 | J118: 2010-12
A119: 536571 | B119: 21790 | C119: VINTAGE SNAP CARDS | D119: 12 | E119: 40513.651 | F119: 0.85 | G119: 14696 | H119: United Kingdom | I119: 10.2 | J119: 2010-12
A120: 536572 | B120: 21754 | C120: HOME BUILDING BLOCK WORD | D120: 6 | E120: 40513.653 | F120: 5.95 | G120: 16539 | H120: United Kingdom | I120: 35.7 | J120: 2010-12
A121: 536572 | B121: 22579 | C121: WOODEN TREE CHRISTMAS SCANDINAVIAN | D121: 24 | E121: 40513.653 | F121: 0.85 | G121: 16539 | H121: United Kingdom | I121: 20.4 | J121: 2010-12
A122: 536575 | B122: 22095 | C122: LADS ONLY TISSUE BOX | D122: 252 | E122: 40513.667 | F122: 1.25 | G122: 13777 | H122: United Kingdom | I122: 315 | J122: 2010-12
... A132: 536591 | B132: 85064 | C132: CREAM SWEETHEART LETTER RACK | D132: 2 | E132: 40513.707 | F132: 5.45 | G132: 14606 | H132: United Kingdom | I132: 10.9 | J132: 2010-12
...

Sheet Data_Cancelled (full 9.251)
A1: InvoiceNo | B1: StockCode | C1: Description | D1: Quantity | E1: InvoiceDate | F1: UnitPrice | G1: CustomerID | H1: Country | I1: TotalPrice | J1: YearMonth
A2: C536379 | B2: D | C2: Discount | D2: -1 | E2: 40513.403 | F2: 27.5 | G2: 14527 | H2: United Kingdom | I2: -27.5 | J2: 2010-12
A3: C536383 | B3: 35004C | C3: SET OF 3 COLOURED FLYING DUCKS | D3: -1 | E3: 40513.409 | F3: 4.65 | G3: 15311 | H3: United Kingdom | I3: -4.65 | J3: 2010-12
A4: C536391 | B4: 22556 | C4: PLASTERS IN TIN CIRCUS PARADE | D4: -12 | E4: 40513.433 | F4: 1.65 | G4: 17548 | H4: United Kingdom | I4: -19.8 | J4: 2010-12
A5: C536391 | B5: 21984 | C5: PACK OF 12 PINK PAISLEY TISSUES | D5: -24 | E5: 40513.433 | F5: 0.29 | G5: 17548 | H5: United Kingdom | I5: -6.96 | J5: 2010-12
A6: C536391 | B6: 21983 | C6: PACK OF 12 BLUE PAISLEY TISSUES | D6: -24 | E6: 40513.433 | F6: 0.29 | G6: 17548 | H6: United Kingdom | I6: -6.96 | J6: 2010-12
A7: C536391 | B7: 21980 | C7: PACK OF 12 RED RETROSPOT TISSUES | D7: -24 | E7: 40513.433 | F7: 0.29 | G7: 17548 | H7: United Kingdom | I7: -6.96 | J7: 2010-12
A8: C536391 | B8: 21484 | C8: CHICK GREY HOT WATER BOTTLE | D8: -12 | E8: 40513.433 | F8: 3.45 | G8: 17548 | H8: United Kingdom | I8: -41.4 | J8: 2010-12
A9: C536391 | B9: 22557 | C9: PLASTERS IN TIN VINTAGE PAISLEY | D9: -12 | E9: 40513.433 | F9: 1.65 | G9: 17548 | H9: United Kingdom | I9: -19.8 | J9: 2010-12
A10: C536391 | B10: 22553 | C10: PLASTERS IN TIN SKULLS | D10: -24 | E10: 40513.433 | F10: 1.65 | G10: 17548 | H10: United Kingdom | I10: -39.6 | J10: 2010-12
A11: C536506 | B11: 22960 | C11: JAM MAKING SET WITH JARS | D11: -6 | E11: 40513.526 | F11: 4.25 | G11: 17897 | H11: United Kingdom | I11: -25.5 | J11: 2010-12
A12: C536543 | B12: 22632 | C12: HAND WARMER RED RETROSPOT | D12: -1 | E12: 40513.604 | F12: 2.1 | G12: 17841 | H12: United Kingdom | I12: -2.1 | J12: 2010-12
A13: C536543 | B13: 22355 | C13: CHARLOTTE BAG SUKI DESIGN | D13: -2 | E13: 40513.604 | F13: 0.85 | G13: 17841 | H13: United Kingdom | I13: -1.7 | J13: 2010-12
... A103: C537234 | B103: 22653 | C103: BUTTON BOX | D103: -20 | E103: 40518.403 | F103: 1.95 | G103: 16161 | H103: United Kingdom | I103: -39 | J103: 2010-12
A104: C537251 | B104: 22429 | C104: ENAMEL MEASURING JUG CREAM | D104: -2 | E104: 40518.448 | F104: 4.25 | H104: United Kingdom | I104: -8.5 | J104: 2010-12
A105: C537251 | B105: 22620 | C105: 4 TRADITIONAL SPINNING TOPS | D105: -8 | E105: 40518.448 | F105: 1.25 | H105: United Kingdom | I105: -10 | J105: 2010-12
A106: C537251 | B106: 21890 | C106: S/6 WOODEN SKITTLES IN COTTON BAG | D106: -2 | E106: 40518.448 | F106: 2.95 | H106: United Kingdom | I106: -5.9 | J106: 2010-12
A107: C537251 | B107: 22564 | C107: ALPHABET STENCIL CRAFT | D107: -5 | E107: 40518.448 | F107: 1.25 | H107: United Kingdom | I107: -6.25 | J107: 2010-12
A108: C537251 | B108: 21891 | C108: TRADITIONAL WOODEN SKIPPING ROPE | D108: -3 | E108: 40518.448 | F108: 1.25 | H108: United Kingdom | I108: -3.75 | J108: 2010-12
A109: C537251 | B109: 22747 | C109: POPPY'S PLAYHOUSE BATHROOM | D109: -6 | E109: 40518.448 | F109: 2.1 | H109: United Kingdom | I109: -12.6 | J109: 2010-12
A110: C537251 | B110: 22454 | C110: MEASURING TAPE BABUSHKA RED | D110: -8 | E110: 40518.448 | F110: 2.95 | H110: United Kingdom | I110: -23.6 | J110: 2010-12
A111: C537251 | B111: 22327 | C111: ROUND SNACK BOXES SET OF 4 SKULLS | D111: -4 | E111: 40518.448 | F111: 2.95 | H111: United Kingdom | I111: -11.8 | J111: 2010-12
A112: C537251 | B112: 21915 | C112: RED HARMONICA IN BOX | D112: -4 | E112: 40518.448 | F112: 1.25 | H112: United Kingdom | I112: -5 | J112: 2010-12
A113: C537251 | B113: 84347 | C113: ROTATING SILVER ANGELS T-LIGHT HLDR | D113: -9 | E113: 40518.448 | F113: 2.55 | H113: United Kingdom | I113: -22.95 | J113: 2010-12
A114: C537251 | B114: 22748 | C114: POPPY'S PLAYHOUSE KITCHEN | D114: -4 | E114: 40518.448 | F114: 2.1 | H114: United Kingdom | I114: -8.4 | J114: 2010-12
A115: C537251 | B115: 22943 | C115: CHRISTMAS LIGHTS 10 VINTAGE BAUBLES | D115: -6 | E115: 40518.448 | F115: 4.95 | H115: United Kingdom | I115: -29.7 | J115: 2010-12
... A123: C537251 | B123: 22466 | C123: FAIRY TALE COTTAGE NIGHTLIGHT | D123: -3 | E123: 40518.448 | F123: 1.95 | H123: United Kingdom | I123: -5.85 | J123: 2010-12
A124: C537314 | B124: 21349 | C124: IVY HEART WREATH | D124: -4 | E124: 40518.488 | F124: 6.75 | G124: 13497 | H124: United Kingdom | I124: -27 | J124: 2010-12
A125: C537320 | B125: 35400 | C125: WOODEN BOX ADVENT CALENDAR | D125: -1 | E125: 40518.491 | F125: 8.95 | G125: 14867 | H125: United Kingdom | I125: -8.95 | J125: 2010-12
A126: C537333 | B126: 22636 | C126: CHILDS BREAKFAST SET CIRCUS PARADE | D126: -4 | E126: 40518.5 | F126: 8.5 | G126: 12474 | H126: Germany | I126: -34 | J126: 2010-12
A127: C537373 | B127: 22423 | C127: REGENCY CAKESTAND 3 TIER | D127: -1 | E127: 40518.538 | F127: 12.75 | G127: 14487 | H127: United Kingdom | I127: -12.75 | J127: 2010-12
A128: C537379 | B128: 22865 | C128: HAND WARMER OWL DESIGN | D128: -10 | E128: 40518.55 | F128: 2.1 | G128: 15882 | H128: United Kingdom | I128: -21 | J128: 2010-12
A129: C537383 | B129: 21658 | C129: GLASS BEURRE DISH | D129: -1 | E129: 40518.553 | F129: 3.95 | G129: 16550 | H129: United Kingdom | I129: -3.95 | J129: 2010-12
A130: C537383 | B130: 22197 | C130: SMALL POPCORN HOLDER | D130: -1 | E130: 40518.553 | F130: 0.85 | G130: 16550 | H130: United Kingdom | I130: -0.85 | J130: 2010-12
A131: C537383 | B131: 22371 | C131: AIRLINE BAG VINTAGE TOKYO 78 | D131: -1 | E131: 40518.553 | F131: 4.25 | G131: 16550 | H131: United Kingdom | I131: -4.25 | J131: 2010-12
A132: C537398 | B132: 22430 | C132: ENAMEL WATERING CAN CREAM | D132: -1 | E132: 40518.599 | F132: 4.95 | G132: 15426 | H132: United Kingdom | I132: -4.95 | J132: 2010-12
A133: C537402 | B133: 22926 | C133: IVORY GIANT GARDEN THERMOMETER | D133: -4 | E133: 40518.613 | F133: 5.95 | G133: 15502 | H133: United Kingdom | I133: -23.8 | J133: 2010-12
A134: C537402 | B134: 22927 | C134: GREEN GIANT GARDEN THERMOMETER | D134: -4 | E134: 40518.613 | F134: 5.95 | G134: 15502 | H134: United Kingdom | I134: -23.8 | J134: 2010-12
A135: C537402 | B135: 22849 | C135: BREAD BIN DINER STYLE MINT | D135: -4 | E135: 40518.613 | F135: 14.95 | G135: 15502 | H135: United Kingdom | I135: -59.8 | J135: 2010-12
... A155: C537530 | B155: 22726 | C155: ALARM CLOCK BAKELIKE GREEN | D155: -2 | E155: 40519.491 | F155: 3.75 | G155: 13319 | H155: United Kingdom | I155: -7.5 | J155: 2010-12
...

Sheet Pivot_Bulanan
B2: REVENUE & ORDER PER BULAN
B3: Revenue/Order/Cancelled dihitung seluruh data (bukan sample) - lihat catatan metodologi di sheet Ringkasan.
B5: Bulan | C5: Revenue (GBP) | D5: Jumlah Order (distinct) | E5: AOV (GBP, formula) | F5: Baris Cancelled | G5: Revenue Hilang (Cancelled)
B6: 2010-12 | C6: 775714.95 | D6: 1550 | E6: =C6/D6 -> 500.46126 | F6: 719 | G6: 74729.12
B7: 2011-01 | C7: 670439.46 | D7: 1081 | E7: =C7/D7 -> 620.20302 | F7: 700 | G7: 131363.05
B8: 2011-02 | C8: 507866.54 | D8: 1093 | E8: =C8/D8 -> 464.65374 | F8: 470 | G8: 25519.15
B9: 2011-03 | C9: 689841.84 | D9: 1440 | E9: =C9/D9 -> 479.05683 | F9: 696 | G9: 34201.28
B10: 2011-04 | C10: 515499.66 | D10: 1236 | E10: =C10/D10 -> 417.07092 | F10: 558 | G10: 44600.65
B11: 2011-05 | C11: 740036.33 | D11: 1668 | E11: =C11/D11 -> 443.66686 | F11: 621 | G11: 47202.51
B12: 2011-06 | C12: 737683.99 | D12: 1525 | E12: =C12/D12 -> 483.72721 | F12: 709 | G12: 70569.78
B13: 2011-07 | C13: 688252.67 | D13: 1452 | E13: =C13/D13 -> 474.00322 | F13: 684 | G13: 37919.13
B14: 2011-08 | C14: 735370.22 | D14: 1340 | E14: =C14/D14 -> 548.78375 | F14: 667 | G14: 54330.8
B15: 2011-09 | C15: 1028345.4 | D15: 1818 | E15: =C15/D15 -> 565.64652 | F15: 801 | G15: 38838.51
B16: 2011-10 | C16: 1103364 | D16: 2006 | E16: =C16/D16 -> 550.03189 | F16: 1194 | G16: 81895.5
B17: 2011-11 | C17: 1452116 | D17: 2751 | E17: =C17/D17 -> 527.85023 | F17: 1073 | G17: 47720.98
B18: 2011-12 | C18: 614499.25 | D18: 816 | E18: =C18/D18 -> 753.06281 | F18: 359 | G18: 205089.27
B20: Catatan: Des 2011 hanya sampai tanggal 9 (data tidak penuh sebulan) - jangan dibandingkan apple-to-apple dgn bulan lain.

Sheet Pivot_Negara
B2: REVENUE PER NEGARA (diurutkan tertinggi)
B4: Negara | C4: Revenue (GBP) | D4: Jumlah Baris Transaksi | E4: % dari Total Revenue (formula)
B5: United Kingdom | C5: 8736254.6 | D5: 478905 | E5: =C5/'Ringkasan & Insight'!$D$7 -> 0.85156729
B6: Netherlands | C6: 283889.34 | D6: 2322 | E6: =C6/'Ringkasan & Insight'!$D$7 -> 0.027672142
B7: EIRE | C7: 270850.86 | D7: 7768 | E7: =C7/'Ringkasan & Insight'!$D$7 -> 0.026401215
B8: Germany | C8: 205381.15 | D8: 8643 | E8: =C8/'Ringkasan & Insight'!$D$7 -> 0.020019548
B9: France | C9: 184493 | D9: 8085 | E9: =C9/'Ringkasan & Insight'!$D$7 -> 0.017983474
B10: Australia | C10: 138103.81 | D10: 1180 | E10: =C10/'Ringkasan & Insight'!$D$7 -> 0.013461683
B11: Spain | C11: 55706.56 | D11: 2417 | E11: =C11/'Ringkasan & Insight'!$D$7 -> 0.0054300025
B12: Switzerland | C12: 53065.6 | D12: 1927 | E12: =C12/'Ringkasan & Insight'!$D$7 -> 0.0051725747
B13: Japan | C13: 37416.37 | D13: 321 | E13: =C13/'Ringkasan & Insight'!$D$7 -> 0.0036471644
B14: Belgium | C14: 36927.34 | D14: 1935 | E14: =C14/'Ringkasan & Insight'!$D$7 -> 0.0035994962
B15: Sweden | C15: 36828.83 | D15: 427 | E15: =C15/'Ringkasan & Insight'!$D$7 -> 0.0035898939
B16: Norway | C16: 32454.64 | D16: 1048 | E16: =C16/'Ringkasan & Insight'!$D$7 -> 0.0031635193
... B42: Saudi Arabia | C42: 145.92 | D42: 9 | E42: =C42/'Ringkasan & Insight'!$D$7 -> 1.4223567e-05

Sheet Pivot_Produk
B2: TOP 15 PRODUK BY REVENUE
B3: PERHATIAN: Rank #2 (23843) dipengaruhi 1 transaksi outlier ~80.995 unit dalam 1 invoice - lihat sheet Ringkasan.
B5: Rank | C5: StockCode | D5: Description | E5: Revenue (GBP) | F5: Qty Terjual
B6: 1 | C6: 22423 | D6: REGENCY CAKESTAND 3 TIER | E6: 174156.54 | F6: 13851
B7: 2 | C7: 23843 | D7: PAPER CRAFT , LITTLE BIRDIE | E7: 168469.6 | F7: 80995
B8: 3 | C8: 85123A | D8: WHITE HANGING HEART T-LIGHT HOLDER | E8: 104284.24 | F8: 37641
B9: 4 | C9: 47566 | D9: PARTY BUNTING | E9: 99445.23 | F9: 18283
B10: 5 | C10: 85099B | D10: JUMBO BAG RED RETROSPOT | E10: 94159.81 | F10: 48371
B11: 6 | C11: 23166 | D11: MEDIUM CERAMIC TOP STORAGE JAR | E11: 81700.92 | F11: 78033
B12: 7 | C12: 23084 | D12: RABBIT NIGHT LIGHT | E12: 66870.03 | F12: 30739
B13: 8 | C13: 22086 | D13: PAPER CHAIN KIT 50'S CHRISTMAS | E13: 64875.59 | F13: 19329
B14: 9 | C14: 84879 | D14: ASSORTED COLOUR BIRD ORNAMENT | E14: 58927.62 | F14: 36362
B15: 10 | C15: 79321 | D15: CHILLI LIGHTS | E15: 54096.36 | F15: 10302
B16: 11 | C16: 23298 | D16: SPOTTY BUNTING | E16: 42513.48 | F16: 8466
B17: 12 | C17: 22386 | D17: JUMBO BAG PINK POLKADOT | E17: 42401.01 | F17: 21448
... B20: 15 | C20: 23284 | D20: DOORMAT KEEP CALM AND COME IN | E20: 38133.64 | F20: 5487

Sheet Pivot_Customer
B2: TOP 15 CUSTOMER BY REVENUE (RFM)
B3: Monetary/Frequency/Recency dihitung Python atas seluruh 522.571 baris (exclude CustomerID kosong).
B5: Rank | C5: CustomerID | D5: Negara | E5: Monetary/Revenue (GBP) | F5: Frequency (order) | G5: Recency (hari)
B6: 1 | C6: 14646 | D6: Netherlands | E6: 279138.02 | F6: 72 | G6: 1
B7: 2 | C7: 18102 | D7: United Kingdom | E7: 259657.3 | F7: 60 | G7: 0
B8: 3 | C8: 17450 | D8: United Kingdom | E8: 194390.79 | F8: 46 | G8: 7
B9: 4 | C9: 16446 | D9: United Kingdom | E9: 168472.5 | F9: 2 | G9: 0
B10: 5 | C10: 14911 | D10: EIRE | E10: 136161.83 | F10: 198 | G10: 0
B11: 6 | C11: 12415 | D11: Australia | E11: 124564.53 | F11: 20 | G11: 23
B12: 7 | C12: 14156 | D12: EIRE | E12: 116560.08 | F12: 54 | G12: 9
B13: 8 | C13: 17511 | D13: United Kingdom | E13: 91062.38 | F13: 31 | G13: 2
B14: 9 | C14: 12346 | D14: United Kingdom | E14: 77183.6 | F14: 1 | G14: 325
B15: 10 | C15: 16029 | D15: United Kingdom | E15: 72708.09 | F15: 62 | G15: 38
B16: 11 | C16: 16684 | D16: United Kingdom | E16: 66653.56 | F16: 28 | G16: 3
B17: 12 | C17: 13694 | D17: United Kingdom | E17: 65039.62 | F17: 50 | G17: 3
... B20: 15 | C20: 17949 | D20: United Kingdom | E20: 58030.48 | F20: 44 | G20: 0
B23: ANALISIS PARETO (dihitung Python, seluruh 4334 customer)
B24: Top 20% customer (866 orang) menyumbang 74.6% total revenue
B25: Hanya 1133 customer (26.1% dari total) sudah menyumbang 80% revenue

Sheet Pola_Waktu
B2: POLA WAKTU TRANSAKSI (Jam & Hari)
B4: Revenue per Jam
B5: Jam | C5: Revenue (GBP)
B6: 0 | C6: 0
B7: 1 | C7: 0
B8: 2 | C8: 0
B9: 3 | C9: 0
B10: 4 | C10: 0
B11: 5 | C11: 0
B12: 6 | C12: 4.25
B13: 7 | C13: 30469.21
B14: 8 | C14: 279297.68
B15: 9 | C15: 955760.16
B16: 10 | C16: 1401791.4
B17: 11 | C17: 1196812.6
... B29: 23 | C29: 0
B32: Revenue per Hari (1=Senin ... 7=Minggu)
B33: Hari | C33: Revenue (GBP)
B34: 1 - Senin | C34: 1683049.6
B35: 2 - Selasa | C35: 2085115.3
B36: 3 - Rabu | C36: 1782498.9
B37: 4 - Kamis | C37: 2131755.6
B38: 5 - Jumat | C38: 1778299.3
B39: 6 - Sabtu | C39: 0
B40: 7 - Minggu | C40: 798311.5
B42: Catatan: tidak ada transaksi hari Sabtu sama sekali di dataset ini (kemungkinan toko/gudang tutup).
